ERROR 2025-08-01 23:34:56,064 log Internal Server Error: /ar/admin/users/users/50/change/
Traceback (most recent call last):
  File "/root/metasoft/hangervenv/lib/python3.10/site-packages/django/db/backends/base/base.py", line 303, in _commit
    return self.connection.commit()
sqlite3.IntegrityError: FOREIGN KEY constraint failed

The above exception was the direct cause of the following exception:

Traceback (most recent call last):
  File "/root/metasoft/hangervenv/lib/python3.10/site-packages/django/core/handlers/exception.py", line 55, in inner
    response = get_response(request)
  File "/root/metasoft/hangervenv/lib/python3.10/site-packages/django/core/handlers/base.py", line 197, in _get_response
    response = wrapped_callback(request, *callback_args, **callback_kwargs)
  File "/root/metasoft/hangervenv/lib/python3.10/site-packages/django/contrib/admin/options.py", line 718, in wrapper
    return self.admin_site.admin_view(view)(*args, **kwargs)
  File "/root/metasoft/hangervenv/lib/python3.10/site-packages/django/utils/decorators.py", line 188, in _view_wrapper
    result = _process_exception(request, e)
  File "/root/metasoft/hangervenv/lib/python3.10/site-packages/django/utils/decorators.py", line 186, in _view_wrapper
    response = view_func(request, *args, **kwargs)
  File "/root/metasoft/hangervenv/lib/python3.10/site-packages/django/views/decorators/cache.py", line 80, in _view_wrapper
    response = view_func(request, *args, **kwargs)
  File "/root/metasoft/hangervenv/lib/python3.10/site-packages/django/contrib/admin/sites.py", line 241, in inner
    return view(request, *args, **kwargs)
  File "/root/metasoft/hangervenv/lib/python3.10/site-packages/django/contrib/admin/options.py", line 1964, in change_view
    return self.changeform_view(request, object_id, form_url, extra_context)
  File "/root/metasoft/hangervenv/lib/python3.10/site-packages/django/utils/decorators.py", line 48, in _wrapper
    return bound_method(*args, **kwargs)
  File "/root/metasoft/hangervenv/lib/python3.10/site-packages/django/utils/decorators.py", line 188, in _view_wrapper
    result = _process_exception(request, e)
  File "/root/metasoft/hangervenv/lib/python3.10/site-packages/django/utils/decorators.py", line 186, in _view_wrapper
    response = view_func(request, *args, **kwargs)
  File "/root/metasoft/hangervenv/lib/python3.10/site-packages/django/contrib/admin/options.py", line 1819, in changeform_view
    with transaction.atomic(using=router.db_for_write(self.model)):
  File "/root/metasoft/hangervenv/lib/python3.10/site-packages/django/db/transaction.py", line 263, in __exit__
    connection.commit()
  File "/root/metasoft/hangervenv/lib/python3.10/site-packages/django/utils/asyncio.py", line 26, in inner
    return func(*args, **kwargs)
  File "/root/metasoft/hangervenv/lib/python3.10/site-packages/django/db/backends/base/base.py", line 327, in commit
    self._commit()
  File "/root/metasoft/hangervenv/lib/python3.10/site-packages/django/db/backends/base/base.py", line 302, in _commit
    with debug_transaction(self, "COMMIT"), self.wrap_database_errors:
  File "/root/metasoft/hangervenv/lib/python3.10/site-packages/django/db/utils.py", line 91, in __exit__
    raise dj_exc_value.with_traceback(traceback) from exc_value
  File "/root/metasoft/hangervenv/lib/python3.10/site-packages/django/db/backends/base/base.py", line 303, in _commit
    return self.connection.commit()
django.db.utils.IntegrityError: FOREIGN KEY constraint failed
