ERROR 2025-06-24 02:01:18,078 log Internal Server Error: /api/cart/filter/
Traceback (most recent call last):
  File "/root/metasoft/hangervenv/lib/python3.10/site-packages/django/db/models/fields/__init__.py", line 2123, in get_prep_value
    return int(value)
ValueError: invalid literal for int() with base 10: 'null'

The above exception was the direct cause of the following exception:

Traceback (most recent call last):
  File "/root/metasoft/hangervenv/lib/python3.10/site-packages/django/core/handlers/exception.py", line 55, in inner
    response = get_response(request)
  File "/root/metasoft/hangervenv/lib/python3.10/site-packages/django/core/handlers/base.py", line 197, in _get_response
    response = wrapped_callback(request, *callback_args, **callback_kwargs)
  File "/root/metasoft/hangervenv/lib/python3.10/site-packages/django/views/decorators/csrf.py", line 65, in _view_wrapper
    return view_func(request, *args, **kwargs)
  File "/root/metasoft/hangervenv/lib/python3.10/site-packages/rest_framework/viewsets.py", line 124, in view
    return self.dispatch(request, *args, **kwargs)
  File "/root/metasoft/hangervenv/lib/python3.10/site-packages/rest_framework/views.py", line 509, in dispatch
    response = self.handle_exception(exc)
  File "/root/metasoft/hangervenv/lib/python3.10/site-packages/rest_framework/views.py", line 469, in handle_exception
    self.raise_uncaught_exception(exc)
  File "/root/metasoft/hangervenv/lib/python3.10/site-packages/rest_framework/views.py", line 480, in raise_uncaught_exception
    raise exc
  File "/root/metasoft/hangervenv/lib/python3.10/site-packages/rest_framework/views.py", line 506, in dispatch
    response = handler(request, *args, **kwargs)
  File "/root/metasoft/hanger_app/orders/views.py", line 59, in filter_by_user_and_laundry
    carts = Cart.objects.filter(user_id=user_id, laundry_id=laundry_id)
  File "/root/metasoft/hangervenv/lib/python3.10/site-packages/django/db/models/manager.py", line 87, in manager_method
    return getattr(self.get_queryset(), name)(*args, **kwargs)
  File "/root/metasoft/hangervenv/lib/python3.10/site-packages/django/db/models/query.py", line 1476, in filter
    return self._filter_or_exclude(False, args, kwargs)
  File "/root/metasoft/hangervenv/lib/python3.10/site-packages/django/db/models/query.py", line 1494, in _filter_or_exclude
    clone._filter_or_exclude_inplace(negate, args, kwargs)
  File "/root/metasoft/hangervenv/lib/python3.10/site-packages/django/db/models/query.py", line 1501, in _filter_or_exclude_inplace
    self._query.add_q(Q(*args, **kwargs))
  File "/root/metasoft/hangervenv/lib/python3.10/site-packages/django/db/models/sql/query.py", line 1609, in add_q
    clause, _ = self._add_q(q_object, self.used_aliases)
  File "/root/metasoft/hangervenv/lib/python3.10/site-packages/django/db/models/sql/query.py", line 1641, in _add_q
    child_clause, needed_inner = self.build_filter(
  File "/root/metasoft/hangervenv/lib/python3.10/site-packages/django/db/models/sql/query.py", line 1555, in build_filter
    condition = self.build_lookup(lookups, col, value)
  File "/root/metasoft/hangervenv/lib/python3.10/site-packages/django/db/models/sql/query.py", line 1385, in build_lookup
    lookup = lookup_class(lhs, rhs)
  File "/root/metasoft/hangervenv/lib/python3.10/site-packages/django/db/models/lookups.py", line 30, in __init__
    self.rhs = self.get_prep_lookup()
  File "/root/metasoft/hangervenv/lib/python3.10/site-packages/django/db/models/fields/related_lookups.py", line 156, in get_prep_lookup
    self.rhs = target_field.get_prep_value(self.rhs)
  File "/root/metasoft/hangervenv/lib/python3.10/site-packages/django/db/models/fields/__init__.py", line 2125, in get_prep_value
    raise e.__class__(
ValueError: Field 'id' expected a number but got 'null'.
ERROR 2025-06-25 17:57:52,779 log Internal Server Error: /api/cart/filter/
Traceback (most recent call last):
  File "/root/metasoft/hangervenv/lib/python3.10/site-packages/django/db/models/fields/__init__.py", line 2123, in get_prep_value
    return int(value)
ValueError: invalid literal for int() with base 10: 'null'

The above exception was the direct cause of the following exception:

Traceback (most recent call last):
  File "/root/metasoft/hangervenv/lib/python3.10/site-packages/django/core/handlers/exception.py", line 55, in inner
    response = get_response(request)
  File "/root/metasoft/hangervenv/lib/python3.10/site-packages/django/core/handlers/base.py", line 197, in _get_response
    response = wrapped_callback(request, *callback_args, **callback_kwargs)
  File "/root/metasoft/hangervenv/lib/python3.10/site-packages/django/views/decorators/csrf.py", line 65, in _view_wrapper
    return view_func(request, *args, **kwargs)
  File "/root/metasoft/hangervenv/lib/python3.10/site-packages/rest_framework/viewsets.py", line 124, in view
    return self.dispatch(request, *args, **kwargs)
  File "/root/metasoft/hangervenv/lib/python3.10/site-packages/rest_framework/views.py", line 509, in dispatch
    response = self.handle_exception(exc)
  File "/root/metasoft/hangervenv/lib/python3.10/site-packages/rest_framework/views.py", line 469, in handle_exception
    self.raise_uncaught_exception(exc)
  File "/root/metasoft/hangervenv/lib/python3.10/site-packages/rest_framework/views.py", line 480, in raise_uncaught_exception
    raise exc
  File "/root/metasoft/hangervenv/lib/python3.10/site-packages/rest_framework/views.py", line 506, in dispatch
    response = handler(request, *args, **kwargs)
  File "/root/metasoft/hanger_app/orders/views.py", line 59, in filter_by_user_and_laundry
    carts = Cart.objects.filter(user_id=user_id, laundry_id=laundry_id)
  File "/root/metasoft/hangervenv/lib/python3.10/site-packages/django/db/models/manager.py", line 87, in manager_method
    return getattr(self.get_queryset(), name)(*args, **kwargs)
  File "/root/metasoft/hangervenv/lib/python3.10/site-packages/django/db/models/query.py", line 1476, in filter
    return self._filter_or_exclude(False, args, kwargs)
  File "/root/metasoft/hangervenv/lib/python3.10/site-packages/django/db/models/query.py", line 1494, in _filter_or_exclude
    clone._filter_or_exclude_inplace(negate, args, kwargs)
  File "/root/metasoft/hangervenv/lib/python3.10/site-packages/django/db/models/query.py", line 1501, in _filter_or_exclude_inplace
    self._query.add_q(Q(*args, **kwargs))
  File "/root/metasoft/hangervenv/lib/python3.10/site-packages/django/db/models/sql/query.py", line 1609, in add_q
    clause, _ = self._add_q(q_object, self.used_aliases)
  File "/root/metasoft/hangervenv/lib/python3.10/site-packages/django/db/models/sql/query.py", line 1641, in _add_q
    child_clause, needed_inner = self.build_filter(
  File "/root/metasoft/hangervenv/lib/python3.10/site-packages/django/db/models/sql/query.py", line 1555, in build_filter
    condition = self.build_lookup(lookups, col, value)
  File "/root/metasoft/hangervenv/lib/python3.10/site-packages/django/db/models/sql/query.py", line 1385, in build_lookup
    lookup = lookup_class(lhs, rhs)
  File "/root/metasoft/hangervenv/lib/python3.10/site-packages/django/db/models/lookups.py", line 30, in __init__
    self.rhs = self.get_prep_lookup()
  File "/root/metasoft/hangervenv/lib/python3.10/site-packages/django/db/models/fields/related_lookups.py", line 156, in get_prep_lookup
    self.rhs = target_field.get_prep_value(self.rhs)
  File "/root/metasoft/hangervenv/lib/python3.10/site-packages/django/db/models/fields/__init__.py", line 2125, in get_prep_value
    raise e.__class__(
ValueError: Field 'id' expected a number but got 'null'.
ERROR 2025-06-29 22:14:10,508 log Internal Server Error: /api/cart/filter/
Traceback (most recent call last):
  File "/root/metasoft/hangervenv/lib/python3.10/site-packages/django/db/models/fields/__init__.py", line 2123, in get_prep_value
    return int(value)
ValueError: invalid literal for int() with base 10: 'null'

The above exception was the direct cause of the following exception:

Traceback (most recent call last):
  File "/root/metasoft/hangervenv/lib/python3.10/site-packages/django/core/handlers/exception.py", line 55, in inner
    response = get_response(request)
  File "/root/metasoft/hangervenv/lib/python3.10/site-packages/django/core/handlers/base.py", line 197, in _get_response
    response = wrapped_callback(request, *callback_args, **callback_kwargs)
  File "/root/metasoft/hangervenv/lib/python3.10/site-packages/django/views/decorators/csrf.py", line 65, in _view_wrapper
    return view_func(request, *args, **kwargs)
  File "/root/metasoft/hangervenv/lib/python3.10/site-packages/rest_framework/viewsets.py", line 124, in view
    return self.dispatch(request, *args, **kwargs)
  File "/root/metasoft/hangervenv/lib/python3.10/site-packages/rest_framework/views.py", line 509, in dispatch
    response = self.handle_exception(exc)
  File "/root/metasoft/hangervenv/lib/python3.10/site-packages/rest_framework/views.py", line 469, in handle_exception
    self.raise_uncaught_exception(exc)
  File "/root/metasoft/hangervenv/lib/python3.10/site-packages/rest_framework/views.py", line 480, in raise_uncaught_exception
    raise exc
  File "/root/metasoft/hangervenv/lib/python3.10/site-packages/rest_framework/views.py", line 506, in dispatch
    response = handler(request, *args, **kwargs)
  File "/root/metasoft/hanger_app/orders/views.py", line 59, in filter_by_user_and_laundry
    carts = Cart.objects.filter(user_id=user_id, laundry_id=laundry_id)
  File "/root/metasoft/hangervenv/lib/python3.10/site-packages/django/db/models/manager.py", line 87, in manager_method
    return getattr(self.get_queryset(), name)(*args, **kwargs)
  File "/root/metasoft/hangervenv/lib/python3.10/site-packages/django/db/models/query.py", line 1476, in filter
    return self._filter_or_exclude(False, args, kwargs)
  File "/root/metasoft/hangervenv/lib/python3.10/site-packages/django/db/models/query.py", line 1494, in _filter_or_exclude
    clone._filter_or_exclude_inplace(negate, args, kwargs)
  File "/root/metasoft/hangervenv/lib/python3.10/site-packages/django/db/models/query.py", line 1501, in _filter_or_exclude_inplace
    self._query.add_q(Q(*args, **kwargs))
  File "/root/metasoft/hangervenv/lib/python3.10/site-packages/django/db/models/sql/query.py", line 1609, in add_q
    clause, _ = self._add_q(q_object, self.used_aliases)
  File "/root/metasoft/hangervenv/lib/python3.10/site-packages/django/db/models/sql/query.py", line 1641, in _add_q
    child_clause, needed_inner = self.build_filter(
  File "/root/metasoft/hangervenv/lib/python3.10/site-packages/django/db/models/sql/query.py", line 1555, in build_filter
    condition = self.build_lookup(lookups, col, value)
  File "/root/metasoft/hangervenv/lib/python3.10/site-packages/django/db/models/sql/query.py", line 1385, in build_lookup
    lookup = lookup_class(lhs, rhs)
  File "/root/metasoft/hangervenv/lib/python3.10/site-packages/django/db/models/lookups.py", line 30, in __init__
    self.rhs = self.get_prep_lookup()
  File "/root/metasoft/hangervenv/lib/python3.10/site-packages/django/db/models/fields/related_lookups.py", line 156, in get_prep_lookup
    self.rhs = target_field.get_prep_value(self.rhs)
  File "/root/metasoft/hangervenv/lib/python3.10/site-packages/django/db/models/fields/__init__.py", line 2125, in get_prep_value
    raise e.__class__(
ValueError: Field 'id' expected a number but got 'null'.
ERROR 2025-07-02 21:53:22,131 log Internal Server Error: /api/order/60
Traceback (most recent call last):
  File "/root/metasoft/hangervenv/lib/python3.10/site-packages/django/core/handlers/exception.py", line 55, in inner
    response = get_response(request)
  File "/root/metasoft/hangervenv/lib/python3.10/site-packages/django/utils/deprecation.py", line 128, in __call__
    response = self.process_request(request)
  File "/root/metasoft/hangervenv/lib/python3.10/site-packages/django/middleware/locale.py", line 24, in process_request
    ) = is_language_prefix_patterns_used(urlconf)
  File "/root/metasoft/hangervenv/lib/python3.10/site-packages/django/conf/urls/i18n.py", line 31, in is_language_prefix_patterns_used
    for url_pattern in get_resolver(urlconf).url_patterns:
  File "/root/metasoft/hangervenv/lib/python3.10/site-packages/django/utils/functional.py", line 47, in __get__
    res = instance.__dict__[self.name] = self.func(instance)
  File "/root/metasoft/hangervenv/lib/python3.10/site-packages/django/urls/resolvers.py", line 718, in url_patterns
    patterns = getattr(self.urlconf_module, "urlpatterns", self.urlconf_module)
  File "/root/metasoft/hangervenv/lib/python3.10/site-packages/django/utils/functional.py", line 47, in __get__
    res = instance.__dict__[self.name] = self.func(instance)
  File "/root/metasoft/hangervenv/lib/python3.10/site-packages/django/urls/resolvers.py", line 711, in urlconf_module
    return import_module(self.urlconf_name)
  File "/usr/lib/python3.10/importlib/__init__.py", line 126, in import_module
    return _bootstrap._gcd_import(name[level:], package, level)
  File "<frozen importlib._bootstrap>", line 1050, in _gcd_import
  File "<frozen importlib._bootstrap>", line 1027, in _find_and_load
  File "<frozen importlib._bootstrap>", line 1006, in _find_and_load_unlocked
  File "<frozen importlib._bootstrap>", line 688, in _load_unlocked
  File "<frozen importlib._bootstrap_external>", line 883, in exec_module
  File "<frozen importlib._bootstrap>", line 241, in _call_with_frames_removed
  File "/root/metasoft/hanger_app/hanger_app/urls.py", line 18, in <module>
    path('api/', include('laundries.urls')),  # Include your app's URLs
  File "/root/metasoft/hangervenv/lib/python3.10/site-packages/django/urls/conf.py", line 39, in include
    urlconf_module = import_module(urlconf_module)
  File "/usr/lib/python3.10/importlib/__init__.py", line 126, in import_module
    return _bootstrap._gcd_import(name[level:], package, level)
  File "<frozen importlib._bootstrap>", line 1050, in _gcd_import
  File "<frozen importlib._bootstrap>", line 1027, in _find_and_load
  File "<frozen importlib._bootstrap>", line 1006, in _find_and_load_unlocked
  File "<frozen importlib._bootstrap>", line 688, in _load_unlocked
  File "<frozen importlib._bootstrap_external>", line 883, in exec_module
  File "<frozen importlib._bootstrap>", line 241, in _call_with_frames_removed
  File "/root/metasoft/hanger_app/laundries/urls.py", line 3, in <module>
    from .views import LaundryOrdersByDateRange, LaundryViewSet,UserLaundryMarkViewSet ,user_laundry_mark_detail,user_laundry_mark_list,user_laundry_mark_delete
  File "/root/metasoft/hanger_app/laundries/views.py", line 10, in <module>
    from .serializers import LaundryOrderSerializer, LaundrySerializer, LaundrySerializerUser
  File "/root/metasoft/hanger_app/laundries/serializers.py", line 63, in <module>
    from users.serializers import UsersSerializer  # تأكد من وجود هذا السيريالايزر أو أنشئه
ImportError: cannot import name 'UserSerializer' from 'users.serializers' (/root/metasoft/hanger_app/users/serializers.py)

During handling of the above exception, another exception occurred:

Traceback (most recent call last):
  File "/root/metasoft/hangervenv/lib/python3.10/site-packages/django/core/handlers/exception.py", line 55, in inner
    response = get_response(request)
  File "/root/metasoft/hangervenv/lib/python3.10/site-packages/django/utils/deprecation.py", line 129, in __call__
    response = response or self.get_response(request)
  File "/root/metasoft/hangervenv/lib/python3.10/site-packages/django/core/handlers/exception.py", line 57, in inner
    response = response_for_exception(request, exc)
  File "/root/metasoft/hangervenv/lib/python3.10/site-packages/django/core/handlers/exception.py", line 140, in response_for_exception
    response = handle_uncaught_exception(
  File "/root/metasoft/hangervenv/lib/python3.10/site-packages/django/core/handlers/exception.py", line 181, in handle_uncaught_exception
    return debug.technical_500_response(request, *exc_info)
  File "/root/metasoft/hangervenv/lib/python3.10/site-packages/django/views/debug.py", line 69, in technical_500_response
    html = reporter.get_traceback_html()
  File "/root/metasoft/hangervenv/lib/python3.10/site-packages/django/views/debug.py", line 428, in get_traceback_html
    c = Context(self.get_traceback_data(), use_l10n=False)
  File "/root/metasoft/hangervenv/lib/python3.10/site-packages/django/views/debug.py", line 411, in get_traceback_data
    c["raising_view_name"] = get_caller(self.request)
  File "/root/metasoft/hangervenv/lib/python3.10/site-packages/django/views/debug.py", line 102, in get_caller
    resolver_match = resolve(request.path)
  File "/root/metasoft/hangervenv/lib/python3.10/site-packages/django/urls/base.py", line 24, in resolve
    return get_resolver(urlconf).resolve(path)
  File "/root/metasoft/hangervenv/lib/python3.10/site-packages/django/urls/resolvers.py", line 666, in resolve
    for pattern in self.url_patterns:
  File "/root/metasoft/hangervenv/lib/python3.10/site-packages/django/utils/functional.py", line 47, in __get__
    res = instance.__dict__[self.name] = self.func(instance)
  File "/root/metasoft/hangervenv/lib/python3.10/site-packages/django/urls/resolvers.py", line 718, in url_patterns
    patterns = getattr(self.urlconf_module, "urlpatterns", self.urlconf_module)
  File "/root/metasoft/hangervenv/lib/python3.10/site-packages/django/utils/functional.py", line 47, in __get__
    res = instance.__dict__[self.name] = self.func(instance)
  File "/root/metasoft/hangervenv/lib/python3.10/site-packages/django/urls/resolvers.py", line 711, in urlconf_module
    return import_module(self.urlconf_name)
  File "/usr/lib/python3.10/importlib/__init__.py", line 126, in import_module
    return _bootstrap._gcd_import(name[level:], package, level)
  File "<frozen importlib._bootstrap>", line 1050, in _gcd_import
  File "<frozen importlib._bootstrap>", line 1027, in _find_and_load
  File "<frozen importlib._bootstrap>", line 1006, in _find_and_load_unlocked
  File "<frozen importlib._bootstrap>", line 688, in _load_unlocked
  File "<frozen importlib._bootstrap_external>", line 883, in exec_module
  File "<frozen importlib._bootstrap>", line 241, in _call_with_frames_removed
  File "/root/metasoft/hanger_app/hanger_app/urls.py", line 18, in <module>
    path('api/', include('laundries.urls')),  # Include your app's URLs
  File "/root/metasoft/hangervenv/lib/python3.10/site-packages/django/urls/conf.py", line 39, in include
    urlconf_module = import_module(urlconf_module)
  File "/usr/lib/python3.10/importlib/__init__.py", line 126, in import_module
    return _bootstrap._gcd_import(name[level:], package, level)
  File "<frozen importlib._bootstrap>", line 1050, in _gcd_import
  File "<frozen importlib._bootstrap>", line 1027, in _find_and_load
  File "<frozen importlib._bootstrap>", line 1006, in _find_and_load_unlocked
  File "<frozen importlib._bootstrap>", line 688, in _load_unlocked
  File "<frozen importlib._bootstrap_external>", line 883, in exec_module
  File "<frozen importlib._bootstrap>", line 241, in _call_with_frames_removed
  File "/root/metasoft/hanger_app/laundries/urls.py", line 3, in <module>
    from .views import LaundryOrdersByDateRange, LaundryViewSet,UserLaundryMarkViewSet ,user_laundry_mark_detail,user_laundry_mark_list,user_laundry_mark_delete
  File "/root/metasoft/hanger_app/laundries/views.py", line 10, in <module>
    from .serializers import LaundryOrderSerializer, LaundrySerializer, LaundrySerializerUser
  File "/root/metasoft/hanger_app/laundries/serializers.py", line 63, in <module>
    from users.serializers import UsersSerializer  # تأكد من وجود هذا السيريالايزر أو أنشئه
ImportError: cannot import name 'UserSerializer' from 'users.serializers' (/root/metasoft/hanger_app/users/serializers.py)

During handling of the above exception, another exception occurred:

Traceback (most recent call last):
  File "/root/metasoft/hangervenv/lib/python3.10/site-packages/django/core/handlers/exception.py", line 55, in inner
    response = get_response(request)
  File "/root/metasoft/hangervenv/lib/python3.10/site-packages/django/utils/deprecation.py", line 129, in __call__
    response = response or self.get_response(request)
  File "/root/metasoft/hangervenv/lib/python3.10/site-packages/django/core/handlers/exception.py", line 57, in inner
    response = response_for_exception(request, exc)
  File "/root/metasoft/hangervenv/lib/python3.10/site-packages/django/core/handlers/exception.py", line 140, in response_for_exception
    response = handle_uncaught_exception(
  File "/root/metasoft/hangervenv/lib/python3.10/site-packages/django/core/handlers/exception.py", line 181, in handle_uncaught_exception
    return debug.technical_500_response(request, *exc_info)
  File "/root/metasoft/hangervenv/lib/python3.10/site-packages/django/views/debug.py", line 69, in technical_500_response
    html = reporter.get_traceback_html()
  File "/root/metasoft/hangervenv/lib/python3.10/site-packages/django/views/debug.py", line 428, in get_traceback_html
    c = Context(self.get_traceback_data(), use_l10n=False)
  File "/root/metasoft/hangervenv/lib/python3.10/site-packages/django/views/debug.py", line 411, in get_traceback_data
    c["raising_view_name"] = get_caller(self.request)
  File "/root/metasoft/hangervenv/lib/python3.10/site-packages/django/views/debug.py", line 102, in get_caller
    resolver_match = resolve(request.path)
  File "/root/metasoft/hangervenv/lib/python3.10/site-packages/django/urls/base.py", line 24, in resolve
    return get_resolver(urlconf).resolve(path)
  File "/root/metasoft/hangervenv/lib/python3.10/site-packages/django/urls/resolvers.py", line 666, in resolve
    for pattern in self.url_patterns:
  File "/root/metasoft/hangervenv/lib/python3.10/site-packages/django/utils/functional.py", line 47, in __get__
    res = instance.__dict__[self.name] = self.func(instance)
  File "/root/metasoft/hangervenv/lib/python3.10/site-packages/django/urls/resolvers.py", line 718, in url_patterns
    patterns = getattr(self.urlconf_module, "urlpatterns", self.urlconf_module)
  File "/root/metasoft/hangervenv/lib/python3.10/site-packages/django/utils/functional.py", line 47, in __get__
    res = instance.__dict__[self.name] = self.func(instance)
  File "/root/metasoft/hangervenv/lib/python3.10/site-packages/django/urls/resolvers.py", line 711, in urlconf_module
    return import_module(self.urlconf_name)
  File "/usr/lib/python3.10/importlib/__init__.py", line 126, in import_module
    return _bootstrap._gcd_import(name[level:], package, level)
  File "<frozen importlib._bootstrap>", line 1050, in _gcd_import
  File "<frozen importlib._bootstrap>", line 1027, in _find_and_load
  File "<frozen importlib._bootstrap>", line 1006, in _find_and_load_unlocked
  File "<frozen importlib._bootstrap>", line 688, in _load_unlocked
  File "<frozen importlib._bootstrap_external>", line 883, in exec_module
  File "<frozen importlib._bootstrap>", line 241, in _call_with_frames_removed
  File "/root/metasoft/hanger_app/hanger_app/urls.py", line 18, in <module>
    path('api/', include('laundries.urls')),  # Include your app's URLs
  File "/root/metasoft/hangervenv/lib/python3.10/site-packages/django/urls/conf.py", line 39, in include
    urlconf_module = import_module(urlconf_module)
  File "/usr/lib/python3.10/importlib/__init__.py", line 126, in import_module
    return _bootstrap._gcd_import(name[level:], package, level)
  File "<frozen importlib._bootstrap>", line 1050, in _gcd_import
  File "<frozen importlib._bootstrap>", line 1027, in _find_and_load
  File "<frozen importlib._bootstrap>", line 1006, in _find_and_load_unlocked
  File "<frozen importlib._bootstrap>", line 688, in _load_unlocked
  File "<frozen importlib._bootstrap_external>", line 883, in exec_module
  File "<frozen importlib._bootstrap>", line 241, in _call_with_frames_removed
  File "/root/metasoft/hanger_app/laundries/urls.py", line 3, in <module>
    from .views import LaundryOrdersByDateRange, LaundryViewSet,UserLaundryMarkViewSet ,user_laundry_mark_detail,user_laundry_mark_list,user_laundry_mark_delete
  File "/root/metasoft/hanger_app/laundries/views.py", line 10, in <module>
    from .serializers import LaundryOrderSerializer, LaundrySerializer, LaundrySerializerUser
  File "/root/metasoft/hanger_app/laundries/serializers.py", line 63, in <module>
    from users.serializers import UsersSerializer  # تأكد من وجود هذا السيريالايزر أو أنشئه
ImportError: cannot import name 'UserSerializer' from 'users.serializers' (/root/metasoft/hanger_app/users/serializers.py)

During handling of the above exception, another exception occurred:

Traceback (most recent call last):
  File "/root/metasoft/hangervenv/lib/python3.10/site-packages/django/core/handlers/exception.py", line 55, in inner
    response = get_response(request)
  File "/root/metasoft/hangervenv/lib/python3.10/site-packages/django/utils/deprecation.py", line 129, in __call__
    response = response or self.get_response(request)
  File "/root/metasoft/hangervenv/lib/python3.10/site-packages/django/core/handlers/exception.py", line 57, in inner
    response = response_for_exception(request, exc)
  File "/root/metasoft/hangervenv/lib/python3.10/site-packages/django/core/handlers/exception.py", line 140, in response_for_exception
    response = handle_uncaught_exception(
  File "/root/metasoft/hangervenv/lib/python3.10/site-packages/django/core/handlers/exception.py", line 181, in handle_uncaught_exception
    return debug.technical_500_response(request, *exc_info)
  File "/root/metasoft/hangervenv/lib/python3.10/site-packages/django/views/debug.py", line 69, in technical_500_response
    html = reporter.get_traceback_html()
  File "/root/metasoft/hangervenv/lib/python3.10/site-packages/django/views/debug.py", line 428, in get_traceback_html
    c = Context(self.get_traceback_data(), use_l10n=False)
  File "/root/metasoft/hangervenv/lib/python3.10/site-packages/django/views/debug.py", line 411, in get_traceback_data
    c["raising_view_name"] = get_caller(self.request)
  File "/root/metasoft/hangervenv/lib/python3.10/site-packages/django/views/debug.py", line 102, in get_caller
    resolver_match = resolve(request.path)
  File "/root/metasoft/hangervenv/lib/python3.10/site-packages/django/urls/base.py", line 24, in resolve
    return get_resolver(urlconf).resolve(path)
  File "/root/metasoft/hangervenv/lib/python3.10/site-packages/django/urls/resolvers.py", line 666, in resolve
    for pattern in self.url_patterns:
  File "/root/metasoft/hangervenv/lib/python3.10/site-packages/django/utils/functional.py", line 47, in __get__
    res = instance.__dict__[self.name] = self.func(instance)
  File "/root/metasoft/hangervenv/lib/python3.10/site-packages/django/urls/resolvers.py", line 718, in url_patterns
    patterns = getattr(self.urlconf_module, "urlpatterns", self.urlconf_module)
  File "/root/metasoft/hangervenv/lib/python3.10/site-packages/django/utils/functional.py", line 47, in __get__
    res = instance.__dict__[self.name] = self.func(instance)
  File "/root/metasoft/hangervenv/lib/python3.10/site-packages/django/urls/resolvers.py", line 711, in urlconf_module
    return import_module(self.urlconf_name)
  File "/usr/lib/python3.10/importlib/__init__.py", line 126, in import_module
    return _bootstrap._gcd_import(name[level:], package, level)
  File "<frozen importlib._bootstrap>", line 1050, in _gcd_import
  File "<frozen importlib._bootstrap>", line 1027, in _find_and_load
  File "<frozen importlib._bootstrap>", line 1006, in _find_and_load_unlocked
  File "<frozen importlib._bootstrap>", line 688, in _load_unlocked
  File "<frozen importlib._bootstrap_external>", line 883, in exec_module
  File "<frozen importlib._bootstrap>", line 241, in _call_with_frames_removed
  File "/root/metasoft/hanger_app/hanger_app/urls.py", line 18, in <module>
    path('api/', include('laundries.urls')),  # Include your app's URLs
  File "/root/metasoft/hangervenv/lib/python3.10/site-packages/django/urls/conf.py", line 39, in include
    urlconf_module = import_module(urlconf_module)
  File "/usr/lib/python3.10/importlib/__init__.py", line 126, in import_module
    return _bootstrap._gcd_import(name[level:], package, level)
  File "<frozen importlib._bootstrap>", line 1050, in _gcd_import
  File "<frozen importlib._bootstrap>", line 1027, in _find_and_load
  File "<frozen importlib._bootstrap>", line 1006, in _find_and_load_unlocked
  File "<frozen importlib._bootstrap>", line 688, in _load_unlocked
  File "<frozen importlib._bootstrap_external>", line 883, in exec_module
  File "<frozen importlib._bootstrap>", line 241, in _call_with_frames_removed
  File "/root/metasoft/hanger_app/laundries/urls.py", line 3, in <module>
    from .views import LaundryOrdersByDateRange, LaundryViewSet,UserLaundryMarkViewSet ,user_laundry_mark_detail,user_laundry_mark_list,user_laundry_mark_delete
  File "/root/metasoft/hanger_app/laundries/views.py", line 10, in <module>
    from .serializers import LaundryOrderSerializer, LaundrySerializer, LaundrySerializerUser
  File "/root/metasoft/hanger_app/laundries/serializers.py", line 63, in <module>
    from users.serializers import UsersSerializer  # تأكد من وجود هذا السيريالايزر أو أنشئه
ImportError: cannot import name 'UserSerializer' from 'users.serializers' (/root/metasoft/hanger_app/users/serializers.py)
ERROR 2025-07-02 23:21:07,300 log Internal Server Error: /api/laundry-orders/date-range/from/2023-01-01/to/2025-01-09/user/24/
Traceback (most recent call last):
  File "/root/metasoft/hangervenv/lib/python3.10/site-packages/django/core/handlers/exception.py", line 55, in inner
    response = get_response(request)
  File "/root/metasoft/hangervenv/lib/python3.10/site-packages/django/core/handlers/base.py", line 197, in _get_response
    response = wrapped_callback(request, *callback_args, **callback_kwargs)
  File "/root/metasoft/hangervenv/lib/python3.10/site-packages/django/views/decorators/csrf.py", line 65, in _view_wrapper
    return view_func(request, *args, **kwargs)
  File "/root/metasoft/hangervenv/lib/python3.10/site-packages/django/views/generic/base.py", line 104, in view
    return self.dispatch(request, *args, **kwargs)
  File "/root/metasoft/hangervenv/lib/python3.10/site-packages/rest_framework/views.py", line 509, in dispatch
    response = self.handle_exception(exc)
  File "/root/metasoft/hangervenv/lib/python3.10/site-packages/rest_framework/views.py", line 469, in handle_exception
    self.raise_uncaught_exception(exc)
  File "/root/metasoft/hangervenv/lib/python3.10/site-packages/rest_framework/views.py", line 480, in raise_uncaught_exception
    raise exc
  File "/root/metasoft/hangervenv/lib/python3.10/site-packages/rest_framework/views.py", line 506, in dispatch
    response = handler(request, *args, **kwargs)
  File "/root/metasoft/hangervenv/lib/python3.10/site-packages/rest_framework/generics.py", line 203, in get
    return self.list(request, *args, **kwargs)
  File "/root/metasoft/hangervenv/lib/python3.10/site-packages/rest_framework/mixins.py", line 38, in list
    queryset = self.filter_queryset(self.get_queryset())
  File "/root/metasoft/hanger_app/laundries/views.py", line 240, in get_queryset
    laundry = Laundry.objects.get(owner_id=user_id)
  File "/root/metasoft/hangervenv/lib/python3.10/site-packages/django/db/models/manager.py", line 87, in manager_method
    return getattr(self.get_queryset(), name)(*args, **kwargs)
  File "/root/metasoft/hangervenv/lib/python3.10/site-packages/django/db/models/query.py", line 649, in get
    raise self.model.DoesNotExist(
laundries.models.Laundry.DoesNotExist: Laundry matching query does not exist.
ERROR 2025-07-03 18:51:46,813 log Internal Server Error: /api/users
Traceback (most recent call last):
  File "/root/metasoft/hangervenv/lib/python3.10/site-packages/django/core/handlers/exception.py", line 55, in inner
    response = get_response(request)
  File "/root/metasoft/hangervenv/lib/python3.10/site-packages/django/utils/deprecation.py", line 131, in __call__
    response = self.process_response(request, response)
  File "/root/metasoft/hangervenv/lib/python3.10/site-packages/django/middleware/common.py", line 108, in process_response
    return self.response_redirect_class(self.get_full_path_with_slash(request))
  File "/root/metasoft/hangervenv/lib/python3.10/site-packages/django/middleware/common.py", line 87, in get_full_path_with_slash
    raise RuntimeError(
RuntimeError: You called this URL via POST, but the URL doesn't end in a slash and you have APPEND_SLASH set. Django can't redirect to the slash URL while maintaining POST data. Change your form to point to hangerapp.com.sa/api/users/ (note the trailing slash), or set APPEND_SLASH=False in your Django settings.
ERROR 2025-07-03 20:09:38,742 log Internal Server Error: /api/users
Traceback (most recent call last):
  File "/root/metasoft/hangervenv/lib/python3.10/site-packages/django/core/handlers/exception.py", line 55, in inner
    response = get_response(request)
  File "/root/metasoft/hangervenv/lib/python3.10/site-packages/django/utils/deprecation.py", line 131, in __call__
    response = self.process_response(request, response)
  File "/root/metasoft/hangervenv/lib/python3.10/site-packages/django/middleware/common.py", line 108, in process_response
    return self.response_redirect_class(self.get_full_path_with_slash(request))
  File "/root/metasoft/hangervenv/lib/python3.10/site-packages/django/middleware/common.py", line 87, in get_full_path_with_slash
    raise RuntimeError(
RuntimeError: You called this URL via POST, but the URL doesn't end in a slash and you have APPEND_SLASH set. Django can't redirect to the slash URL while maintaining POST data. Change your form to point to www.hangerapp.com.sa/api/users/ (note the trailing slash), or set APPEND_SLASH=False in your Django settings.
ERROR 2025-07-03 22:44:27,693 log Internal Server Error: /api/users
Traceback (most recent call last):
  File "/root/metasoft/hangervenv/lib/python3.10/site-packages/django/core/handlers/exception.py", line 55, in inner
    response = get_response(request)
  File "/root/metasoft/hangervenv/lib/python3.10/site-packages/django/utils/deprecation.py", line 131, in __call__
    response = self.process_response(request, response)
  File "/root/metasoft/hangervenv/lib/python3.10/site-packages/django/middleware/common.py", line 108, in process_response
    return self.response_redirect_class(self.get_full_path_with_slash(request))
  File "/root/metasoft/hangervenv/lib/python3.10/site-packages/django/middleware/common.py", line 87, in get_full_path_with_slash
    raise RuntimeError(
RuntimeError: You called this URL via POST, but the URL doesn't end in a slash and you have APPEND_SLASH set. Django can't redirect to the slash URL while maintaining POST data. Change your form to point to hangerapp.com.sa/api/users/ (note the trailing slash), or set APPEND_SLASH=False in your Django settings.
ERROR 2025-07-04 00:02:59,665 log Internal Server Error: /api/users
Traceback (most recent call last):
  File "/root/metasoft/hangervenv/lib/python3.10/site-packages/django/core/handlers/exception.py", line 55, in inner
    response = get_response(request)
  File "/root/metasoft/hangervenv/lib/python3.10/site-packages/django/utils/deprecation.py", line 131, in __call__
    response = self.process_response(request, response)
  File "/root/metasoft/hangervenv/lib/python3.10/site-packages/django/middleware/common.py", line 108, in process_response
    return self.response_redirect_class(self.get_full_path_with_slash(request))
  File "/root/metasoft/hangervenv/lib/python3.10/site-packages/django/middleware/common.py", line 87, in get_full_path_with_slash
    raise RuntimeError(
RuntimeError: You called this URL via POST, but the URL doesn't end in a slash and you have APPEND_SLASH set. Django can't redirect to the slash URL while maintaining POST data. Change your form to point to www.hangerapp.com.sa/api/users/ (note the trailing slash), or set APPEND_SLASH=False in your Django settings.
ERROR 2025-07-04 11:33:31,716 log Internal Server Error: /api/users
Traceback (most recent call last):
  File "/root/metasoft/hangervenv/lib/python3.10/site-packages/django/core/handlers/exception.py", line 55, in inner
    response = get_response(request)
  File "/root/metasoft/hangervenv/lib/python3.10/site-packages/django/utils/deprecation.py", line 131, in __call__
    response = self.process_response(request, response)
  File "/root/metasoft/hangervenv/lib/python3.10/site-packages/django/middleware/common.py", line 108, in process_response
    return self.response_redirect_class(self.get_full_path_with_slash(request))
  File "/root/metasoft/hangervenv/lib/python3.10/site-packages/django/middleware/common.py", line 87, in get_full_path_with_slash
    raise RuntimeError(
RuntimeError: You called this URL via POST, but the URL doesn't end in a slash and you have APPEND_SLASH set. Django can't redirect to the slash URL while maintaining POST data. Change your form to point to hangerapp.com.sa/api/users/ (note the trailing slash), or set APPEND_SLASH=False in your Django settings.
ERROR 2025-07-04 12:49:14,741 log Internal Server Error: /api/users
Traceback (most recent call last):
  File "/root/metasoft/hangervenv/lib/python3.10/site-packages/django/core/handlers/exception.py", line 55, in inner
    response = get_response(request)
  File "/root/metasoft/hangervenv/lib/python3.10/site-packages/django/utils/deprecation.py", line 131, in __call__
    response = self.process_response(request, response)
  File "/root/metasoft/hangervenv/lib/python3.10/site-packages/django/middleware/common.py", line 108, in process_response
    return self.response_redirect_class(self.get_full_path_with_slash(request))
  File "/root/metasoft/hangervenv/lib/python3.10/site-packages/django/middleware/common.py", line 87, in get_full_path_with_slash
    raise RuntimeError(
RuntimeError: You called this URL via POST, but the URL doesn't end in a slash and you have APPEND_SLASH set. Django can't redirect to the slash URL while maintaining POST data. Change your form to point to www.hangerapp.com.sa/api/users/ (note the trailing slash), or set APPEND_SLASH=False in your Django settings.
ERROR 2025-07-07 19:13:51,597 log Internal Server Error: /api/users
Traceback (most recent call last):
  File "/root/metasoft/hangervenv/lib/python3.10/site-packages/django/core/handlers/exception.py", line 55, in inner
    response = get_response(request)
  File "/root/metasoft/hangervenv/lib/python3.10/site-packages/django/utils/deprecation.py", line 131, in __call__
    response = self.process_response(request, response)
  File "/root/metasoft/hangervenv/lib/python3.10/site-packages/django/middleware/common.py", line 108, in process_response
    return self.response_redirect_class(self.get_full_path_with_slash(request))
  File "/root/metasoft/hangervenv/lib/python3.10/site-packages/django/middleware/common.py", line 87, in get_full_path_with_slash
    raise RuntimeError(
RuntimeError: You called this URL via POST, but the URL doesn't end in a slash and you have APPEND_SLASH set. Django can't redirect to the slash URL while maintaining POST data. Change your form to point to hangerapp.com.sa/api/users/ (note the trailing slash), or set APPEND_SLASH=False in your Django settings.
ERROR 2025-07-07 20:17:26,515 log Internal Server Error: /api/users
Traceback (most recent call last):
  File "/root/metasoft/hangervenv/lib/python3.10/site-packages/django/core/handlers/exception.py", line 55, in inner
    response = get_response(request)
  File "/root/metasoft/hangervenv/lib/python3.10/site-packages/django/utils/deprecation.py", line 131, in __call__
    response = self.process_response(request, response)
  File "/root/metasoft/hangervenv/lib/python3.10/site-packages/django/middleware/common.py", line 108, in process_response
    return self.response_redirect_class(self.get_full_path_with_slash(request))
  File "/root/metasoft/hangervenv/lib/python3.10/site-packages/django/middleware/common.py", line 87, in get_full_path_with_slash
    raise RuntimeError(
RuntimeError: You called this URL via POST, but the URL doesn't end in a slash and you have APPEND_SLASH set. Django can't redirect to the slash URL while maintaining POST data. Change your form to point to www.hangerapp.com.sa/api/users/ (note the trailing slash), or set APPEND_SLASH=False in your Django settings.
ERROR 2025-07-07 23:29:37,591 log Internal Server Error: /api/users
Traceback (most recent call last):
  File "/root/metasoft/hangervenv/lib/python3.10/site-packages/django/core/handlers/exception.py", line 55, in inner
    response = get_response(request)
  File "/root/metasoft/hangervenv/lib/python3.10/site-packages/django/utils/deprecation.py", line 131, in __call__
    response = self.process_response(request, response)
  File "/root/metasoft/hangervenv/lib/python3.10/site-packages/django/middleware/common.py", line 108, in process_response
    return self.response_redirect_class(self.get_full_path_with_slash(request))
  File "/root/metasoft/hangervenv/lib/python3.10/site-packages/django/middleware/common.py", line 87, in get_full_path_with_slash
    raise RuntimeError(
RuntimeError: You called this URL via POST, but the URL doesn't end in a slash and you have APPEND_SLASH set. Django can't redirect to the slash URL while maintaining POST data. Change your form to point to hangerapp.com.sa/api/users/ (note the trailing slash), or set APPEND_SLASH=False in your Django settings.
ERROR 2025-07-08 00:38:43,528 log Internal Server Error: /api/users
Traceback (most recent call last):
  File "/root/metasoft/hangervenv/lib/python3.10/site-packages/django/core/handlers/exception.py", line 55, in inner
    response = get_response(request)
  File "/root/metasoft/hangervenv/lib/python3.10/site-packages/django/utils/deprecation.py", line 131, in __call__
    response = self.process_response(request, response)
  File "/root/metasoft/hangervenv/lib/python3.10/site-packages/django/middleware/common.py", line 108, in process_response
    return self.response_redirect_class(self.get_full_path_with_slash(request))
  File "/root/metasoft/hangervenv/lib/python3.10/site-packages/django/middleware/common.py", line 87, in get_full_path_with_slash
    raise RuntimeError(
RuntimeError: You called this URL via POST, but the URL doesn't end in a slash and you have APPEND_SLASH set. Django can't redirect to the slash URL while maintaining POST data. Change your form to point to www.hangerapp.com.sa/api/users/ (note the trailing slash), or set APPEND_SLASH=False in your Django settings.
ERROR 2025-07-08 11:31:39,559 log Internal Server Error: /api/users
Traceback (most recent call last):
  File "/root/metasoft/hangervenv/lib/python3.10/site-packages/django/core/handlers/exception.py", line 55, in inner
    response = get_response(request)
  File "/root/metasoft/hangervenv/lib/python3.10/site-packages/django/utils/deprecation.py", line 131, in __call__
    response = self.process_response(request, response)
  File "/root/metasoft/hangervenv/lib/python3.10/site-packages/django/middleware/common.py", line 108, in process_response
    return self.response_redirect_class(self.get_full_path_with_slash(request))
  File "/root/metasoft/hangervenv/lib/python3.10/site-packages/django/middleware/common.py", line 87, in get_full_path_with_slash
    raise RuntimeError(
RuntimeError: You called this URL via POST, but the URL doesn't end in a slash and you have APPEND_SLASH set. Django can't redirect to the slash URL while maintaining POST data. Change your form to point to hangerapp.com.sa/api/users/ (note the trailing slash), or set APPEND_SLASH=False in your Django settings.
ERROR 2025-07-08 12:49:56,353 log Internal Server Error: /api/users
Traceback (most recent call last):
  File "/root/metasoft/hangervenv/lib/python3.10/site-packages/django/core/handlers/exception.py", line 55, in inner
    response = get_response(request)
  File "/root/metasoft/hangervenv/lib/python3.10/site-packages/django/utils/deprecation.py", line 131, in __call__
    response = self.process_response(request, response)
  File "/root/metasoft/hangervenv/lib/python3.10/site-packages/django/middleware/common.py", line 108, in process_response
    return self.response_redirect_class(self.get_full_path_with_slash(request))
  File "/root/metasoft/hangervenv/lib/python3.10/site-packages/django/middleware/common.py", line 87, in get_full_path_with_slash
    raise RuntimeError(
RuntimeError: You called this URL via POST, but the URL doesn't end in a slash and you have APPEND_SLASH set. Django can't redirect to the slash URL while maintaining POST data. Change your form to point to www.hangerapp.com.sa/api/users/ (note the trailing slash), or set APPEND_SLASH=False in your Django settings.
ERROR 2025-07-09 13:35:38,245 log Internal Server Error: /api/cart/filter/
Traceback (most recent call last):
  File "/root/metasoft/hangervenv/lib/python3.10/site-packages/django/db/models/fields/__init__.py", line 2123, in get_prep_value
    return int(value)
ValueError: invalid literal for int() with base 10: 'null'

The above exception was the direct cause of the following exception:

Traceback (most recent call last):
  File "/root/metasoft/hangervenv/lib/python3.10/site-packages/django/core/handlers/exception.py", line 55, in inner
    response = get_response(request)
  File "/root/metasoft/hangervenv/lib/python3.10/site-packages/django/core/handlers/base.py", line 197, in _get_response
    response = wrapped_callback(request, *callback_args, **callback_kwargs)
  File "/root/metasoft/hangervenv/lib/python3.10/site-packages/django/views/decorators/csrf.py", line 65, in _view_wrapper
    return view_func(request, *args, **kwargs)
  File "/root/metasoft/hangervenv/lib/python3.10/site-packages/rest_framework/viewsets.py", line 124, in view
    return self.dispatch(request, *args, **kwargs)
  File "/root/metasoft/hangervenv/lib/python3.10/site-packages/rest_framework/views.py", line 509, in dispatch
    response = self.handle_exception(exc)
  File "/root/metasoft/hangervenv/lib/python3.10/site-packages/rest_framework/views.py", line 469, in handle_exception
    self.raise_uncaught_exception(exc)
  File "/root/metasoft/hangervenv/lib/python3.10/site-packages/rest_framework/views.py", line 480, in raise_uncaught_exception
    raise exc
  File "/root/metasoft/hangervenv/lib/python3.10/site-packages/rest_framework/views.py", line 506, in dispatch
    response = handler(request, *args, **kwargs)
  File "/root/metasoft/hanger_app/orders/views.py", line 59, in filter_by_user_and_laundry
    carts = Cart.objects.filter(user_id=user_id, laundry_id=laundry_id)
  File "/root/metasoft/hangervenv/lib/python3.10/site-packages/django/db/models/manager.py", line 87, in manager_method
    return getattr(self.get_queryset(), name)(*args, **kwargs)
  File "/root/metasoft/hangervenv/lib/python3.10/site-packages/django/db/models/query.py", line 1476, in filter
    return self._filter_or_exclude(False, args, kwargs)
  File "/root/metasoft/hangervenv/lib/python3.10/site-packages/django/db/models/query.py", line 1494, in _filter_or_exclude
    clone._filter_or_exclude_inplace(negate, args, kwargs)
  File "/root/metasoft/hangervenv/lib/python3.10/site-packages/django/db/models/query.py", line 1501, in _filter_or_exclude_inplace
    self._query.add_q(Q(*args, **kwargs))
  File "/root/metasoft/hangervenv/lib/python3.10/site-packages/django/db/models/sql/query.py", line 1609, in add_q
    clause, _ = self._add_q(q_object, self.used_aliases)
  File "/root/metasoft/hangervenv/lib/python3.10/site-packages/django/db/models/sql/query.py", line 1641, in _add_q
    child_clause, needed_inner = self.build_filter(
  File "/root/metasoft/hangervenv/lib/python3.10/site-packages/django/db/models/sql/query.py", line 1555, in build_filter
    condition = self.build_lookup(lookups, col, value)
  File "/root/metasoft/hangervenv/lib/python3.10/site-packages/django/db/models/sql/query.py", line 1385, in build_lookup
    lookup = lookup_class(lhs, rhs)
  File "/root/metasoft/hangervenv/lib/python3.10/site-packages/django/db/models/lookups.py", line 30, in __init__
    self.rhs = self.get_prep_lookup()
  File "/root/metasoft/hangervenv/lib/python3.10/site-packages/django/db/models/fields/related_lookups.py", line 156, in get_prep_lookup
    self.rhs = target_field.get_prep_value(self.rhs)
  File "/root/metasoft/hangervenv/lib/python3.10/site-packages/django/db/models/fields/__init__.py", line 2125, in get_prep_value
    raise e.__class__(
ValueError: Field 'id' expected a number but got 'null'.
ERROR 2025-07-09 13:36:11,633 log Internal Server Error: /api/cart/filter/
Traceback (most recent call last):
  File "/root/metasoft/hangervenv/lib/python3.10/site-packages/django/db/models/fields/__init__.py", line 2123, in get_prep_value
    return int(value)
ValueError: invalid literal for int() with base 10: 'null'

The above exception was the direct cause of the following exception:

Traceback (most recent call last):
  File "/root/metasoft/hangervenv/lib/python3.10/site-packages/django/core/handlers/exception.py", line 55, in inner
    response = get_response(request)
  File "/root/metasoft/hangervenv/lib/python3.10/site-packages/django/core/handlers/base.py", line 197, in _get_response
    response = wrapped_callback(request, *callback_args, **callback_kwargs)
  File "/root/metasoft/hangervenv/lib/python3.10/site-packages/django/views/decorators/csrf.py", line 65, in _view_wrapper
    return view_func(request, *args, **kwargs)
  File "/root/metasoft/hangervenv/lib/python3.10/site-packages/rest_framework/viewsets.py", line 124, in view
    return self.dispatch(request, *args, **kwargs)
  File "/root/metasoft/hangervenv/lib/python3.10/site-packages/rest_framework/views.py", line 509, in dispatch
    response = self.handle_exception(exc)
  File "/root/metasoft/hangervenv/lib/python3.10/site-packages/rest_framework/views.py", line 469, in handle_exception
    self.raise_uncaught_exception(exc)
  File "/root/metasoft/hangervenv/lib/python3.10/site-packages/rest_framework/views.py", line 480, in raise_uncaught_exception
    raise exc
  File "/root/metasoft/hangervenv/lib/python3.10/site-packages/rest_framework/views.py", line 506, in dispatch
    response = handler(request, *args, **kwargs)
  File "/root/metasoft/hanger_app/orders/views.py", line 59, in filter_by_user_and_laundry
    carts = Cart.objects.filter(user_id=user_id, laundry_id=laundry_id)
  File "/root/metasoft/hangervenv/lib/python3.10/site-packages/django/db/models/manager.py", line 87, in manager_method
    return getattr(self.get_queryset(), name)(*args, **kwargs)
  File "/root/metasoft/hangervenv/lib/python3.10/site-packages/django/db/models/query.py", line 1476, in filter
    return self._filter_or_exclude(False, args, kwargs)
  File "/root/metasoft/hangervenv/lib/python3.10/site-packages/django/db/models/query.py", line 1494, in _filter_or_exclude
    clone._filter_or_exclude_inplace(negate, args, kwargs)
  File "/root/metasoft/hangervenv/lib/python3.10/site-packages/django/db/models/query.py", line 1501, in _filter_or_exclude_inplace
    self._query.add_q(Q(*args, **kwargs))
  File "/root/metasoft/hangervenv/lib/python3.10/site-packages/django/db/models/sql/query.py", line 1609, in add_q
    clause, _ = self._add_q(q_object, self.used_aliases)
  File "/root/metasoft/hangervenv/lib/python3.10/site-packages/django/db/models/sql/query.py", line 1641, in _add_q
    child_clause, needed_inner = self.build_filter(
  File "/root/metasoft/hangervenv/lib/python3.10/site-packages/django/db/models/sql/query.py", line 1555, in build_filter
    condition = self.build_lookup(lookups, col, value)
  File "/root/metasoft/hangervenv/lib/python3.10/site-packages/django/db/models/sql/query.py", line 1385, in build_lookup
    lookup = lookup_class(lhs, rhs)
  File "/root/metasoft/hangervenv/lib/python3.10/site-packages/django/db/models/lookups.py", line 30, in __init__
    self.rhs = self.get_prep_lookup()
  File "/root/metasoft/hangervenv/lib/python3.10/site-packages/django/db/models/fields/related_lookups.py", line 156, in get_prep_lookup
    self.rhs = target_field.get_prep_value(self.rhs)
  File "/root/metasoft/hangervenv/lib/python3.10/site-packages/django/db/models/fields/__init__.py", line 2125, in get_prep_value
    raise e.__class__(
ValueError: Field 'id' expected a number but got 'null'.
ERROR 2025-07-11 22:25:39,104 log Internal Server Error: /api/cart/filter/
Traceback (most recent call last):
  File "/root/metasoft/hangervenv/lib/python3.10/site-packages/django/db/models/fields/__init__.py", line 2123, in get_prep_value
    return int(value)
ValueError: invalid literal for int() with base 10: 'null'

The above exception was the direct cause of the following exception:

Traceback (most recent call last):
  File "/root/metasoft/hangervenv/lib/python3.10/site-packages/django/core/handlers/exception.py", line 55, in inner
    response = get_response(request)
  File "/root/metasoft/hangervenv/lib/python3.10/site-packages/django/core/handlers/base.py", line 197, in _get_response
    response = wrapped_callback(request, *callback_args, **callback_kwargs)
  File "/root/metasoft/hangervenv/lib/python3.10/site-packages/django/views/decorators/csrf.py", line 65, in _view_wrapper
    return view_func(request, *args, **kwargs)
  File "/root/metasoft/hangervenv/lib/python3.10/site-packages/rest_framework/viewsets.py", line 124, in view
    return self.dispatch(request, *args, **kwargs)
  File "/root/metasoft/hangervenv/lib/python3.10/site-packages/rest_framework/views.py", line 509, in dispatch
    response = self.handle_exception(exc)
  File "/root/metasoft/hangervenv/lib/python3.10/site-packages/rest_framework/views.py", line 469, in handle_exception
    self.raise_uncaught_exception(exc)
  File "/root/metasoft/hangervenv/lib/python3.10/site-packages/rest_framework/views.py", line 480, in raise_uncaught_exception
    raise exc
  File "/root/metasoft/hangervenv/lib/python3.10/site-packages/rest_framework/views.py", line 506, in dispatch
    response = handler(request, *args, **kwargs)
  File "/root/metasoft/hanger_app/orders/views.py", line 59, in filter_by_user_and_laundry
    carts = Cart.objects.filter(user_id=user_id, laundry_id=laundry_id)
  File "/root/metasoft/hangervenv/lib/python3.10/site-packages/django/db/models/manager.py", line 87, in manager_method
    return getattr(self.get_queryset(), name)(*args, **kwargs)
  File "/root/metasoft/hangervenv/lib/python3.10/site-packages/django/db/models/query.py", line 1476, in filter
    return self._filter_or_exclude(False, args, kwargs)
  File "/root/metasoft/hangervenv/lib/python3.10/site-packages/django/db/models/query.py", line 1494, in _filter_or_exclude
    clone._filter_or_exclude_inplace(negate, args, kwargs)
  File "/root/metasoft/hangervenv/lib/python3.10/site-packages/django/db/models/query.py", line 1501, in _filter_or_exclude_inplace
    self._query.add_q(Q(*args, **kwargs))
  File "/root/metasoft/hangervenv/lib/python3.10/site-packages/django/db/models/sql/query.py", line 1609, in add_q
    clause, _ = self._add_q(q_object, self.used_aliases)
  File "/root/metasoft/hangervenv/lib/python3.10/site-packages/django/db/models/sql/query.py", line 1641, in _add_q
    child_clause, needed_inner = self.build_filter(
  File "/root/metasoft/hangervenv/lib/python3.10/site-packages/django/db/models/sql/query.py", line 1555, in build_filter
    condition = self.build_lookup(lookups, col, value)
  File "/root/metasoft/hangervenv/lib/python3.10/site-packages/django/db/models/sql/query.py", line 1385, in build_lookup
    lookup = lookup_class(lhs, rhs)
  File "/root/metasoft/hangervenv/lib/python3.10/site-packages/django/db/models/lookups.py", line 30, in __init__
    self.rhs = self.get_prep_lookup()
  File "/root/metasoft/hangervenv/lib/python3.10/site-packages/django/db/models/fields/related_lookups.py", line 156, in get_prep_lookup
    self.rhs = target_field.get_prep_value(self.rhs)
  File "/root/metasoft/hangervenv/lib/python3.10/site-packages/django/db/models/fields/__init__.py", line 2125, in get_prep_value
    raise e.__class__(
ValueError: Field 'id' expected a number but got 'null'.
ERROR 2025-07-11 22:25:41,497 log Internal Server Error: /api/cart/filter/
Traceback (most recent call last):
  File "/root/metasoft/hangervenv/lib/python3.10/site-packages/django/db/models/fields/__init__.py", line 2123, in get_prep_value
    return int(value)
ValueError: invalid literal for int() with base 10: 'null'

The above exception was the direct cause of the following exception:

Traceback (most recent call last):
  File "/root/metasoft/hangervenv/lib/python3.10/site-packages/django/core/handlers/exception.py", line 55, in inner
    response = get_response(request)
  File "/root/metasoft/hangervenv/lib/python3.10/site-packages/django/core/handlers/base.py", line 197, in _get_response
    response = wrapped_callback(request, *callback_args, **callback_kwargs)
  File "/root/metasoft/hangervenv/lib/python3.10/site-packages/django/views/decorators/csrf.py", line 65, in _view_wrapper
    return view_func(request, *args, **kwargs)
  File "/root/metasoft/hangervenv/lib/python3.10/site-packages/rest_framework/viewsets.py", line 124, in view
    return self.dispatch(request, *args, **kwargs)
  File "/root/metasoft/hangervenv/lib/python3.10/site-packages/rest_framework/views.py", line 509, in dispatch
    response = self.handle_exception(exc)
  File "/root/metasoft/hangervenv/lib/python3.10/site-packages/rest_framework/views.py", line 469, in handle_exception
    self.raise_uncaught_exception(exc)
  File "/root/metasoft/hangervenv/lib/python3.10/site-packages/rest_framework/views.py", line 480, in raise_uncaught_exception
    raise exc
  File "/root/metasoft/hangervenv/lib/python3.10/site-packages/rest_framework/views.py", line 506, in dispatch
    response = handler(request, *args, **kwargs)
  File "/root/metasoft/hanger_app/orders/views.py", line 59, in filter_by_user_and_laundry
    carts = Cart.objects.filter(user_id=user_id, laundry_id=laundry_id)
  File "/root/metasoft/hangervenv/lib/python3.10/site-packages/django/db/models/manager.py", line 87, in manager_method
    return getattr(self.get_queryset(), name)(*args, **kwargs)
  File "/root/metasoft/hangervenv/lib/python3.10/site-packages/django/db/models/query.py", line 1476, in filter
    return self._filter_or_exclude(False, args, kwargs)
  File "/root/metasoft/hangervenv/lib/python3.10/site-packages/django/db/models/query.py", line 1494, in _filter_or_exclude
    clone._filter_or_exclude_inplace(negate, args, kwargs)
  File "/root/metasoft/hangervenv/lib/python3.10/site-packages/django/db/models/query.py", line 1501, in _filter_or_exclude_inplace
    self._query.add_q(Q(*args, **kwargs))
  File "/root/metasoft/hangervenv/lib/python3.10/site-packages/django/db/models/sql/query.py", line 1609, in add_q
    clause, _ = self._add_q(q_object, self.used_aliases)
  File "/root/metasoft/hangervenv/lib/python3.10/site-packages/django/db/models/sql/query.py", line 1641, in _add_q
    child_clause, needed_inner = self.build_filter(
  File "/root/metasoft/hangervenv/lib/python3.10/site-packages/django/db/models/sql/query.py", line 1555, in build_filter
    condition = self.build_lookup(lookups, col, value)
  File "/root/metasoft/hangervenv/lib/python3.10/site-packages/django/db/models/sql/query.py", line 1385, in build_lookup
    lookup = lookup_class(lhs, rhs)
  File "/root/metasoft/hangervenv/lib/python3.10/site-packages/django/db/models/lookups.py", line 30, in __init__
    self.rhs = self.get_prep_lookup()
  File "/root/metasoft/hangervenv/lib/python3.10/site-packages/django/db/models/fields/related_lookups.py", line 156, in get_prep_lookup
    self.rhs = target_field.get_prep_value(self.rhs)
  File "/root/metasoft/hangervenv/lib/python3.10/site-packages/django/db/models/fields/__init__.py", line 2125, in get_prep_value
    raise e.__class__(
ValueError: Field 'id' expected a number but got 'null'.
ERROR 2025-07-12 23:41:52,371 log Internal Server Error: /api/order/62/update-status/
Traceback (most recent call last):
  File "/root/metasoft/hangervenv/lib/python3.10/site-packages/django/core/handlers/exception.py", line 55, in inner
    response = get_response(request)
  File "/root/metasoft/hangervenv/lib/python3.10/site-packages/django/core/handlers/base.py", line 197, in _get_response
    response = wrapped_callback(request, *callback_args, **callback_kwargs)
  File "/root/metasoft/hangervenv/lib/python3.10/site-packages/django/views/decorators/csrf.py", line 65, in _view_wrapper
    return view_func(request, *args, **kwargs)
  File "/root/metasoft/hangervenv/lib/python3.10/site-packages/django/views/generic/base.py", line 104, in view
    return self.dispatch(request, *args, **kwargs)
  File "/root/metasoft/hangervenv/lib/python3.10/site-packages/rest_framework/views.py", line 509, in dispatch
    response = self.handle_exception(exc)
  File "/root/metasoft/hangervenv/lib/python3.10/site-packages/rest_framework/views.py", line 469, in handle_exception
    self.raise_uncaught_exception(exc)
  File "/root/metasoft/hangervenv/lib/python3.10/site-packages/rest_framework/views.py", line 480, in raise_uncaught_exception
    raise exc
  File "/root/metasoft/hangervenv/lib/python3.10/site-packages/rest_framework/views.py", line 506, in dispatch
    response = handler(request, *args, **kwargs)
  File "/root/metasoft/hanger_app/orders/views.py", line 408, in patch
    sales_agent = SalesAgent.objects.get(user_id=user_id)
  File "/root/metasoft/hangervenv/lib/python3.10/site-packages/django/db/models/manager.py", line 87, in manager_method
    return getattr(self.get_queryset(), name)(*args, **kwargs)
  File "/root/metasoft/hangervenv/lib/python3.10/site-packages/django/db/models/query.py", line 649, in get
    raise self.model.DoesNotExist(
agent.models.SalesAgent.DoesNotExist: SalesAgent matching query does not exist.
ERROR 2025-07-12 23:43:14,509 log Internal Server Error: /api/order/62/update-status/
Traceback (most recent call last):
  File "/root/metasoft/hangervenv/lib/python3.10/site-packages/django/core/handlers/exception.py", line 55, in inner
    response = get_response(request)
  File "/root/metasoft/hangervenv/lib/python3.10/site-packages/django/core/handlers/base.py", line 197, in _get_response
    response = wrapped_callback(request, *callback_args, **callback_kwargs)
  File "/root/metasoft/hangervenv/lib/python3.10/site-packages/django/views/decorators/csrf.py", line 65, in _view_wrapper
    return view_func(request, *args, **kwargs)
  File "/root/metasoft/hangervenv/lib/python3.10/site-packages/django/views/generic/base.py", line 104, in view
    return self.dispatch(request, *args, **kwargs)
  File "/root/metasoft/hangervenv/lib/python3.10/site-packages/rest_framework/views.py", line 509, in dispatch
    response = self.handle_exception(exc)
  File "/root/metasoft/hangervenv/lib/python3.10/site-packages/rest_framework/views.py", line 469, in handle_exception
    self.raise_uncaught_exception(exc)
  File "/root/metasoft/hangervenv/lib/python3.10/site-packages/rest_framework/views.py", line 480, in raise_uncaught_exception
    raise exc
  File "/root/metasoft/hangervenv/lib/python3.10/site-packages/rest_framework/views.py", line 506, in dispatch
    response = handler(request, *args, **kwargs)
  File "/root/metasoft/hanger_app/orders/views.py", line 408, in patch
    sales_agent = SalesAgent.objects.get(user_id=user_id)
  File "/root/metasoft/hangervenv/lib/python3.10/site-packages/django/db/models/manager.py", line 87, in manager_method
    return getattr(self.get_queryset(), name)(*args, **kwargs)
  File "/root/metasoft/hangervenv/lib/python3.10/site-packages/django/db/models/query.py", line 649, in get
    raise self.model.DoesNotExist(
agent.models.SalesAgent.DoesNotExist: SalesAgent matching query does not exist.
ERROR 2025-07-12 23:44:28,058 log Internal Server Error: /api/order/62/update-status/
Traceback (most recent call last):
  File "/root/metasoft/hangervenv/lib/python3.10/site-packages/django/core/handlers/exception.py", line 55, in inner
    response = get_response(request)
  File "/root/metasoft/hangervenv/lib/python3.10/site-packages/django/core/handlers/base.py", line 197, in _get_response
    response = wrapped_callback(request, *callback_args, **callback_kwargs)
  File "/root/metasoft/hangervenv/lib/python3.10/site-packages/django/views/decorators/csrf.py", line 65, in _view_wrapper
    return view_func(request, *args, **kwargs)
  File "/root/metasoft/hangervenv/lib/python3.10/site-packages/django/views/generic/base.py", line 104, in view
    return self.dispatch(request, *args, **kwargs)
  File "/root/metasoft/hangervenv/lib/python3.10/site-packages/rest_framework/views.py", line 509, in dispatch
    response = self.handle_exception(exc)
  File "/root/metasoft/hangervenv/lib/python3.10/site-packages/rest_framework/views.py", line 469, in handle_exception
    self.raise_uncaught_exception(exc)
  File "/root/metasoft/hangervenv/lib/python3.10/site-packages/rest_framework/views.py", line 480, in raise_uncaught_exception
    raise exc
  File "/root/metasoft/hangervenv/lib/python3.10/site-packages/rest_framework/views.py", line 506, in dispatch
    response = handler(request, *args, **kwargs)
  File "/root/metasoft/hanger_app/orders/views.py", line 408, in patch
    sales_agent = SalesAgent.objects.get(user_id=user_id)
  File "/root/metasoft/hangervenv/lib/python3.10/site-packages/django/db/models/manager.py", line 87, in manager_method
    return getattr(self.get_queryset(), name)(*args, **kwargs)
  File "/root/metasoft/hangervenv/lib/python3.10/site-packages/django/db/models/query.py", line 649, in get
    raise self.model.DoesNotExist(
agent.models.SalesAgent.DoesNotExist: SalesAgent matching query does not exist.
